{% macro UndampedCartPole(Mp, lp, Jp) %}
<robot name="UndampedCartPole">

  <link name="cart">
    <inertial>
      <origin xyz="0 0 0" />
      <mass value="1.0731" />
    </inertial>
  </link>

  <link name="pendulum">
    <inertial>
      <origin xyz="0 0 {{ lp }}" />
      <mass value="{{ Mp }}" />
      <inertia ixx="{{ Jp }}" ixy="0.0" ixz="0.0" iyy="{{ Jp }}" iyz="0.0" izz="{{ Jp }}"/>
    </inertial>
  </link>

  <joint name="x" type="prismatic">
    <parent link="world" />
    <child link="cart" />
    <axis xyz="1 0 0" />
    <dynamics damping="5.4"/>
  </joint>

  <joint name="theta" type="continuous">
    <parent link="cart" />
    <child link="pendulum" />
    <axis xyz="0 -1 0" />
    <dynamics damping="0.0024"/>
  </joint>

  <transmission type="SimpleTransmission" name="base_force">
    <actuator name="force" />
    <joint name="x" />
  </transmission>

</robot>
{%- endmacro %}